Workbook

Sheet Assumptions
D2: https://maps.app.goo.gl/yFKfXytVnSZRiYGC9 | E2: Hada Land 35,000 m2
D3: Fund Name | E3: xxx | L3: بالريال السعودي
D4: Fund Type | E4: صندوق استثمار عقاري خاص | L4: السنة | N4: 2025 | O4: 2026 | P4: 2027
D5: Fund Period- year | E5: 3 | N5: Y1 | O5: Y2 | P5: Y3
D6: Fund Size- SAR | E6: =F54 -> 5.41638e+08 | L6: التدفقات النقدية الداخلة
D7: Total Equity | E7: =F57 -> 3.7830466e+08 | L7: المبيعات | N7: 0 | O7: 0 | P7: =Assumptions!H33 -> 656250000
L8: الإجمالي | N8: =SUM(N7) -> 0 | O8: 0 | P8: =SUM(P7) -> 656250000
B9: الأرض | D9: افتراضات الأرض | L9: التدفقات النقدية الخارجة | N9: 0 | P9: 0
F10: الإجمالي | H10: النقدي | I10: العيني | N10: 0 | P10: 0
D11: مساحة الأرض | F11: 35000 | H11: 1 | I11: 0 | L11: إجمالي الاستحواذ على الأرض | N11: =Assumptions!E66*Assumptions!$F$16 -> 264293750 | O11: =Assumptions!F66*Assumptions!$F$16 -> 0 | P11: =Assumptions!G66*Assumptions!$F$16 -> 0
D12: سعر الاستحواذ بالمتر | E12: 7000 | F12: =$E$12*F11 -> 245000000 | H12: =H11*$F$16 -> 264293750 | I12: =I11*F12 -> 0 | L12: التكاليف المباشرة | N12: =Assumptions!E69*Assumptions!$H$23 -> 61875000 | O12: =Assumptions!F69*Assumptions!$H$23 -> 84375000 | P12: =Assumptions!G69*Assumptions!$H$23 -> 41250000
D13: السعي | E13: 0.025 | F13: =$E$13*F12 -> 6125000 | L13: التكاليف غير المباشرة | N13: =Assumptions!$H$28*Assumptions!E72 -> 12993750 | O13: =Assumptions!$H$28*Assumptions!F72 -> 17718750 | P13: =Assumptions!$H$28*Assumptions!G72 -> 8662500
D14: ضريبة التصرفات العقارية | E14: 0.05 | F14: =E14*F12 -> 12250000 | L14: فوائد تمويل | N14: =Assumptions!$E$38*N37 -> 8000000 | O14: =Assumptions!$E$38*O37 -> 13066667 | P14: =Assumptions!$E$38*P37 -> 13066667
D15: ضريبة السعي | E15: 0.15 | F15: =E15*F13 -> 918750 | L15: أتعاب ترتيب تمويل | N15: =Assumptions!E39*Assumptions!F59 -> 3266666.7 | O15: 0 | P15: 0
D16: الإجمالي | F16: =SUM(F12:F15) -> 264293750 | L16: =Assumptions!D40 -> رسوم إدارة الصندوق | N16: =Assumptions!$E$40*(SUM(Assumptions!N11:N13)) -> 5087437.5 | O16: =Assumptions!$E$40*(SUM(Assumptions!O11:O13)) -> 1531406.2 | P16: =Assumptions!$E$40*(SUM(Assumptions!P11:P13)) -> 748687.5
L17: =Assumptions!D41 -> رسوم أمين الحفظ | N17: =Assumptions!$E$41 -> 50000 | O17: =Assumptions!$E$41 -> 50000 | P17: =Assumptions!$E$41 -> 50000
B18: التكاليف | D18: افتراضات التكاليف | L18: =Assumptions!D42 -> مجلس الإدارة | N18: =Assumptions!$E$42 -> 100000 | O18: =Assumptions!$E$42 -> 100000 | P18: =Assumptions!$E$42 -> 100000
D19: التكاليف المباشرة | E19: % | F19: المساحة | G19: التكلفة/ متر | H19: الإجمالي | L19: =Assumptions!D43 -> إصدار الشهادة الشرعية للصندوق | N19: =Assumptions!E43 -> 5000 | O19: 0 | P19: 0
D20: تطوير البنية التحتية | E20: 1 | F20: 52500 | G20: 500 | H20: =G20*F20 -> 26250000 | L20: =Assumptions!D44 -> أتعاب الهيئة الشرعية | N20: =Assumptions!$E$44 -> 5000 | O20: =Assumptions!$E$44 -> 5000 | P20: =Assumptions!$E$44 -> 5000
D21: تطوير البنية العلوية | F21: =F20 -> 52500 | G21: 2500 | H21: =G21*F21 -> 131250000 | L21: =Assumptions!D45 -> مستشار قانوني | N21: =Assumptions!E45 -> 50000 | O21: 0 | P21: 0
D22: مواقف(قبو) | F22: 15000 | G22: 2000 | H22: =G22*F22 -> 30000000 | L22: =Assumptions!D46 -> مراجع الحسابات | N22: =Assumptions!$E$46 -> 50000 | O22: =Assumptions!$E$46 -> 50000 | P22: =Assumptions!$E$46 -> 50000
D23: إجمالي التكاليف المباشرة | E23: - | F23: - | G23: - | H23: =SUM(H20:H22) -> 187500000 | L23: =Assumptions!D47 -> التقييم | N23: =Assumptions!$E$47*4 -> 80000 | O23: =Assumptions!$E$47*4 -> 80000 | P23: =Assumptions!$E$47*4 -> 80000
D24: التكاليف غير المباشرة | E24: % | F24: الإجمالي | L24: =Assumptions!D48 -> احتياطي مصروفات أخرى | N24: =Assumptions!$E$48*SUM(Assumptions!N11:N13) -> 169581.25 | O24: =Assumptions!$E$48*SUM(Assumptions!O11:O13) -> 51046.875 | P24: =Assumptions!$E$48*SUM(Assumptions!P11:P13) -> 24956.25
D25: أتعاب المطور | E25: 0.1 | F25: =E25*H23 -> 18750000 | L25: =Assumptions!D49 -> رسوم إنشاء الشركة ذات الغرض الخاص | N25: =Assumptions!E49 -> 25000 | O25: 0 | P25: 0
D26: تكاليف غير مباشرة أخرى | E26: 0.06 | F26: =E26*H23 -> 11250000 | L26: =Assumptions!D50 -> رسوم هيكلة | N26: =Assumptions!E50*Assumptions!G60 -> 3784377.6 | O26: 0 | P26: 0
D27: احتياطي | E27: 0.05 | F27: =E27*H23 -> 9375000 | L27: =Assumptions!D51 -> أتعاب المشغل | N27: =Assumptions!$E$51*(SUM(Assumptions!N11:N13)) -> 508743.75 | O27: =Assumptions!$E$51*(SUM(Assumptions!O11:O13)) -> 153140.62 | P27: =Assumptions!$E$51*(SUM(Assumptions!P11:P13)) -> 74868.75
D28: إجمالي التكاليف غير المباشرة | H28: =F25+F26+F27 -> 39375000 | L28: الإجمالي | N28: =SUM(N11:N27) -> 3.6034431e+08 | O28: =SUM(O11:O27) -> 1.1718101e+08 | P28: =SUM(P11:P27) -> 64112679
D29: إجمالي التكاليف المباشرة وغير المباشرة | H29: =H28+H23 -> 226875000
L30: صافي التدفقات النقدية | N30: =N8-N28-N29 -> -3.6034431e+08 | O30: =O8-O28-O29 -> -1.1718101e+08 | P30: =P8-P28-P29 -> 5.9213732e+08
B31: المبيعات | D31: افتراضات المبيعات | E31: % | F31: المساحة | G31: قيمة المتر | H31: إجمالي المبيعات | L31: Cumulative Cash Flow | N31: =N30 -> -3.6034431e+08 | O31: =O30+N31 -> -4.7752532e+08 | P31: =P30+O31 -> 1.14612e+08
D32: بيع شقق سكنية | F32: =F20 -> 52500 | G32: 12500 | H32: =G32*F32 -> 656250000 | N32: =N31+N35 -> -3.6034431e+08
D33: الإجمالي | H33: =H32 -> 656250000 | L33: تمويل رأس مال الصندوق
L34: =Assumptions!D57 -> Equity | N34: =Assumptions!F57 -> 3.7830466e+08 | P34: 0
L35: In-Kind Contribution | N35: =Assumptions!I12 -> 0 | P35: 0
B36: رسوم الصندوق والتمويل | D36: Financing & Fund Cost Assumptions | L36: Debt Withdrawl | N36: 100000000 | O36: =63333333 -> 63333333 | P36: =Assumptions!F59-Assumptions!N36-Assumptions!O36 -> 0.33333331
D37: Cost | F37: Total (SAR) | L37: Debt Outstanding | N37: =N36 -> 100000000 | O37: =O36+N37 -> 163333333 | P37: =P36+O37 -> 1.6333333e+08
D38: =Assumptions!L14 -> فوائد تمويل | E38: 0.08 | F38: =SUM(Assumptions!N14:P14) -> 34133333 | L38: Debt Repayment | N38: 0 | O38: 0 | P38: =P37 -> 1.6333333e+08
D39: =Assumptions!L15 -> أتعاب ترتيب تمويل | E39: 0.02 | F39: =SUM(Assumptions!N15:P15) -> 3266666.7 | L39: Beginning Cash | N39: 0 | O39: =N40 -> 1.1796036e+08 | P39: =O40 -> 64112679
D40: رسوم إدارة الصندوق | E40: 0.015 | F40: =SUM(Assumptions!N16:P16) -> 7367531.2 | L40: Net Cashflows | N40: =N30+SUM(N34,N35,N36,-N38,N39) -> 1.1796036e+08 | O40: =O30+SUM(O34,O35,O36,-O38,O39) -> 64112679 | P40: =P30+SUM(P34,P35,P36,-P38,P39) -> 4.9291667e+08
D41: رسوم أمين الحفظ | E41: 50000 | F41: =SUM(Assumptions!N17:P17) -> 150000 | L41: Net Equity Cashflow | M41: =-N34-N35 -> -3.7830466e+08 | N41: 0 | O41: 0 | P41: =P40 -> 4.9291667e+08
...

Sheet CF
I41: Debt Withdrawl = | J41: 1.0019475e+08
